Workbook
Name Print_Area: 'HC 2610 06 02 2025 CAB2'!$A$1:$C$39
Name Print_Area: 'HC 2610 15 05 2023 CAB 2'!$A$1:$D$38
Name Print_Area: 'HC 2610 16 05 2023 CAB1 '!$A$1:$D$38
Name Print_Area: 'HC 2610 21 09 2023 CAB1'!$A$1:$C$39
Name Print_Area: 'HC 2610 21 09 2023 CAB2'!$A$1:$C$39
Name Print_Area: 'HC 2610 24 05 2023 CAB1 '!$A$1:$D$38
Name Print_Area: 'HC 2610 24 05 2024 CAB1'!$A$1:$C$39
Name Print_Area: 'HC 2610 24 05 2024 CAB2'!$A$1:$C$39
Name Print_Area: 'HC 2610 25 10 2023 CAB1'!$A$1:$C$39
Name Print_Area: 'HC 2610 25 10 2023 CAB2'!$A$1:$C$39
Name Print_Area: 'HC 2610 26 07 2023 CAB1'!$A$1:$C$39
Name Print_Area: 'HC 2610 26 07 2023 CAB2'!$A$1:$C$39
Name Print_Area: 'HC 2610 26 09 2023 CAB1'!$A$1:$C$39
Name Print_Area: 'HC 2610 26 09 2023 CAB2'!$A$1:$C$39
Name Print_Area: 'PAINÉIS CONSUMO'!$A$1:$H$34
Name Print_Area: 'PARAMETROS CR 11575'!$A$1:$D$20
Name Print_Area: 'PARAMETROS HC 1091'!$A$1:$D$37
Name Print_Area: 'PARAMETROS HC 1091 9'!$A$1:$D$37
Name Print_Area: 'PARAMETROS HC 1266 150-100-6'!$A$1:$D$37
Name Print_Area: 'PARAMETROS HC 1266 154-100-6'!$A$1:$D$37
Name Print_Area: 'PARAMETROS HC 2610'!$A$1:$D$38
Name Print_Area: 'PARAMETROS HC 2610 08 02 2023'!$A$1:$D$38
Name Print_Area: 'PARAMETROS HC 2610 17 03 2023'!$A$1:$D$38
Name Print_Area: 'SKIN CONSUMO'!$A$1:$J$14
Name Print_Titles: 'PAINÉIS CONSUMO'!$1:$3

Sheet RELAÇÃO
A1: AVALIAÇÃO
A2: ESPECIFICAÇÕES | B2: Unidade | C2: CR 1157 | D2: CD 1266 | E2: CR 1183 | F2: CR 1091
A3: Partes de Isocianato | B3: p | C3: 130 | D3: 150 | E3: 165 | F3: 147
A4: % Isocianato | B4: % | C4: =C3/(C3+C5+C7) -> 0.56521739 | D4: =D3/(D3+D5+D7) -> 0.5859375 | E4: =E3/(E3+E5+E7) -> 0.59139785 | F4: =F3/(F3+F5+F7) -> 0.56538462
A5: Partes de Poliol | B5: p | C5: 100 | D5: 100 | E5: 100 | F5: 100
A6: % Poliol | B6: % | C6: =C5/(C3+C5+C7) -> 0.43478261 | D6: =D5/(D3+D5+D7) -> 0.390625 | E6: =E5/(E3+E5+E7) -> 0.35842294 | F6: =F5/(F3+F5+F7) -> 0.38461538
A7: Partes de HC | B7: p | C7: 0 | D7: 6 | E7: 14 | F7: 13
A8: % HC | B8: % | C8: 0 | D8: =D7/(D3+D5+D7) -> 0.0234375 | E8: =E7/(E3+E5+E7) -> 0.050179211 | F8: =F7/(F3+F5+F7) -> 0.05
A9: % Poliol + HC | B9: % | C9: 0 | D9: =(D5+D7)/(D3+D5+D7) -> 0.4140625 | E9: =(E5+E7)/(E3+E5+E7) -> 0.40860215 | F9: =(F5+F7)/(F3+F5+F7) -> 0.43461538
A10: Relação | B10: i/P | C10: =C3/(C5+C7) -> 1.3 | D10: =D3/(D5+D7) -> 1.4150943 | E10: =E3/(E5+E7) -> 1.4473684 | F10: =F3/(F5+F7) -> 1.300885
A11: Vazão Máxima | B11: Kg/s | C11: 2.2 | D11: 2.3 | E11: 2.3 | F11: 2.3
A12: Vazão Isocianato | B12: Kg/s | C12: =C11/2 -> 1.1 | D12: =D11/2 -> 1.15 | E12: =E11/2 -> 1.15 | F12: =F11/2 -> 1.15
A13: Vazão Poliol | B13: Kg/s | C13: =(C6*C12)/C4 -> 0.84615385 | D13: =(D9*D12)/D4 -> 0.81266667 | E13: =(E9*E12)/E4 -> 0.79454545 | F13: =(F9*F12)/F4 -> 0.88401361
A14: Vazão Total Final | B14: Kg/s | C14: =C12+C13 -> 1.9461538 | D14: =D12+D13 -> 1.9626667 | E14: =E12+E13 -> 1.9445455 | F14: =F12+F13 -> 2.0340136
A15: Maior Volume Injeção | B15: Kg | C15: 16 | D15: 16 | E15: 16 | F15: 16
A16: Tempo Injeção | B16: s | C16: =C15/C14 -> 8.2213439 | D16: =D15/D14 -> 8.1521739 | E16: =E15/E14 -> 8.228144 | F16: =F15/F14 -> 7.8662207

Sheet SKIN CONSUMO
A1: CONSUMO DE HIDROCARBONETOS (CICLOPENTANO, CICLOISOPENTANO OU N-PENTANO)
A2: ITEM | B2: DESCRIÇÃO | C2: MASSA INJETADA (g) | D2: VOLUME (m3) | E2: DENSIDADE (Kg/m3) | F2: MASSA POLIOL (g) | G2: MASSA ISOCIANATO (g) | H2: MASSA HC (g) | I2: PREVISÃO PRODUÇÃO ANUAL | J2: MASSA TOTAL HC ANUAL (Kg)
A4: EK001402 | B4: KIT MODULO BASICO NICFD 1850C VD | C4: 11300 | D4: 0.266 | E4: =(C4/1000)/D4 -> 42.481203 | F4: =C4*RELAÇÃO!$D$6 -> 4414.0625 | G4: =C4*RELAÇÃO!$D$4 -> 6621.0938 | H4: =C4*RELAÇÃO!$D$8 -> 264.84375 | I4: 100 | J4: =I4*H4/1000 -> 26.484375
A5: EK001403 | B5: KIT MODULO BASICO NICFD 1850C SLD | C5: 12100 | D5: 0.286 | E5: =(C5/1000)/D5 -> 42.307692 | F5: =C5*RELAÇÃO!$D$6 -> 4726.5625 | G5: =C5*RELAÇÃO!$D$4 -> 7089.8438 | H5: =C5*RELAÇÃO!$D$8 -> 283.59375 | I5: 60 | J5: =I5*H5/1000 -> 17.015625
A6: EK001404 | B6: KIT MODULO BASICO NICFD 2100C VD | C6: 13100 | D6: 0.295 | E6: =(C6/1000)/D6 -> 44.40678 | F6: =C6*RELAÇÃO!$D$6 -> 5117.1875 | G6: =C6*RELAÇÃO!$D$4 -> 7675.7812 | H6: =C6*RELAÇÃO!$D$8 -> 307.03125 | I6: 3593 | J6: =I6*H6/1000 -> 1103.1633
A7: EK001405 | B7: KIT MODULO BASICO NICFD 2100C SLD | C7: 14200 | D7: 0.318 | E7: =(C7/1000)/D7 -> 44.654088 | F7: =C7*RELAÇÃO!$D$6 -> 5546.875 | G7: =C7*RELAÇÃO!$D$4 -> 8320.3125 | H7: =C7*RELAÇÃO!$D$8 -> 332.8125 | I7: 7672 | J7: =I7*H7/1000 -> 2553.3375
A8: EK001406 | B8: KIT MODULO BASICO NICFD 2500C VD | C8: 15300 | D8: 0.342 | E8: =(C8/1000)/D8 -> 44.736842 | F8: =C8*RELAÇÃO!$D$6 -> 5976.5625 | G8: =C8*RELAÇÃO!$D$4 -> 8964.8438 | H8: =C8*RELAÇÃO!$D$8 -> 358.59375 | I8: 1154 | J8: =I8*H8/1000 -> 413.81719
A9: EK001407 | B9: KIT MODULO BASICO NICFD 2500C SLD | C9: 16700 | D9: 0.369 | E9: =(C9/1000)/D9 -> 45.257453 | F9: =C9*RELAÇÃO!$D$6 -> 6523.4375 | G9: =C9*RELAÇÃO!$D$4 -> 9785.1562 | H9: =C9*RELAÇÃO!$D$8 -> 391.40625 | I9: 3458 | J9: =I9*H9/1000 -> 1353.4828
A10: EK001400 | B10: KIT MODULO BASICO NICFD 1850T VD | C10: 10500 | D10: 0.242 | E10: =(C10/1000)/D10 -> 43.38843 | F10: =C10*RELAÇÃO!$D$6 -> 4101.5625 | G10: =C10*RELAÇÃO!$D$4 -> 6152.3438 | H10: =C10*RELAÇÃO!$D$8 -> 246.09375 | I10: 1619 | J10: =I10*H10/1000 -> 398.42578
A11: EK001401 | B11: KIT MODULO BASICO NICFD 1850T SLD | C11: 12000 | D11: 0.279 | E11: =(C11/1000)/D11 -> 43.010753 | F11: =C11*RELAÇÃO!$D$6 -> 4687.5 | G11: =C11*RELAÇÃO!$D$4 -> 7031.25 | H11: =C11*RELAÇÃO!$D$8 -> 281.25 | I11: 2719 | J11: =I11*H11/1000 -> 764.71875
A12: EK001711 | B12: KIT MODULO BASICO NICFD 2100T SLD | C12: 14000 | D12: 0.31 | E12: =(C12/1000)/D12 -> 45.16129 | F12: =C12*RELAÇÃO!$D$6 -> 5468.75 | G12: =C12*RELAÇÃO!$D$4 -> 8203.125 | H12: =C12*RELAÇÃO!$D$8 -> 328.125 | I12: 25 | J12: =I12*H12/1000 -> 8.203125
A13: TOTAL ANUAL | I13: =SUM(I4:I12) -> 20400 | J13: =SUM(J4:J12) -> 6638.6484
A14: OBS.: Considerando o sistema CD1266 + CE164 + C-pentano

Sheet PAINÉIS CONSUMO
A1: CONSUMO DE HIDROCARBONETOS (CICLOPENTANO, CICLOISOPENTANO OU N-PENTANO)
A2: ITEM | B2: DESCRIÇÃO | C2: MASSA INJETADA (g) | D2: MASSA POLIOL (g) | E2: MASSA ISOCIANATO (g) | F2: MASSA HC (g) | G2: PREVISÃO PRODUÇÃO ANUAL | H2: MASSA TOTAL HC ANUAL (Kg)
A4: 59011289600 | B4: CABECEIRA FECHADA | C4: 2100 | D4: =C4*RELAÇÃO!$D$6 -> 820.3125 | E4: =C4*RELAÇÃO!$D$4 -> 1230.4688 | F4: =C4*RELAÇÃO!$D$8 -> 49.21875 | G4: 647 | H4: =G4*F4/1000 -> 31.844531
A5: 59011229100 | B5: CABECEIRA VIDRO | C5: 700 | D5: =C5*RELAÇÃO!$D$6 -> 273.4375 | E5: =C5*RELAÇÃO!$D$4 -> 410.15625 | F5: =C5*RELAÇÃO!$D$8 -> 16.40625 | G5: 363 | H5: =G5*F5/1000 -> 5.9554687
A6: 59012036900 | B6: CABECEIRA FECHADA | C6: 1000 | D6: =C6*RELAÇÃO!$D$6 -> 390.625 | E6: =C6*RELAÇÃO!$D$4 -> 585.9375 | F6: =C6*RELAÇÃO!$D$8 -> 23.4375 | G6: 347 | H6: =G6*F6/1000 -> 8.1328125
A7: 59009096300 | B7: CABECEIRA FECHADA | C7: 1500 | D7: =C7*RELAÇÃO!$D$6 -> 585.9375 | E7: =C7*RELAÇÃO!$D$4 -> 878.90625 | F7: =C7*RELAÇÃO!$D$8 -> 35.15625 | G7: 134 | H7: =G7*F7/1000 -> 4.7109375
A8: 59009093100 | B8: PAINEL TRASEIRO | C8: 3930 | D8: =C8*RELAÇÃO!$D$6 -> 1535.1562 | E8: =C8*RELAÇÃO!$D$4 -> 2302.7344 | F8: =C8*RELAÇÃO!$D$8 -> 92.109375 | G8: 122 | H8: =G8*F8/1000 -> 11.237344
A9: 59009093000 | B9: PAINEL TETO | C9: 2900 | D9: =C9*RELAÇÃO!$D$6 -> 1132.8125 | E9: =C9*RELAÇÃO!$D$4 -> 1699.2188 | F9: =C9*RELAÇÃO!$D$8 -> 67.96875 | G9: 122 | H9: =G9*F9/1000 -> 8.2921875
A10: 59011259600 | B10: PAINEL INFERIOR | C10: 7200 | D10: =C10*RELAÇÃO!$D$6 -> 2812.5 | E10: =C10*RELAÇÃO!$D$4 -> 4218.75 | F10: =C10*RELAÇÃO!$D$8 -> 168.75 | G10: 117 | H10: =G10*F10/1000 -> 19.74375
A11: 59011264700 | B11: TANQUE | C11: 7200 | D11: =C11*RELAÇÃO!$D$6 -> 2812.5 | E11: =C11*RELAÇÃO!$D$4 -> 4218.75 | F11: =C11*RELAÇÃO!$D$8 -> 168.75 | G11: 117 | H11: =G11*F11/1000 -> 19.74375
A12: 59011260200 | B12: PAINEL SUPERIOR | C12: 3200 | D12: =C12*RELAÇÃO!$D$6 -> 1250 | E12: =C12*RELAÇÃO!$D$4 -> 1875 | F12: =C12*RELAÇÃO!$D$8 -> 75 | G12: 117 | H12: =G12*F12/1000 -> 8.775
A13: 59011259900 | B13: PAINEL TETO | C13: 2700 | D13: =C13*RELAÇÃO!$D$6 -> 1054.6875 | E13: =C13*RELAÇÃO!$D$4 -> 1582.0312 | F13: =C13*RELAÇÃO!$D$8 -> 63.28125 | G13: 117 | H13: =G13*F13/1000 -> 7.4039063
A14: 59009106700 | B14: CABECEIRA FECHADA | C14: 2450 | D14: =C14*RELAÇÃO!$D$6 -> 957.03125 | E14: =C14*RELAÇÃO!$D$4 -> 1435.5469 | F14: =C14*RELAÇÃO!$D$8 -> 57.421875 | G14: 97 | H14: =G14*F14/1000 -> 5.5699219
A15: 59011258800 | B15: CABECEIRA FECHADA | C15: 2300 | D15: =C15*RELAÇÃO!$D$6 -> 898.4375 | E15: =C15*RELAÇÃO!$D$4 -> 1347.6562 | F15: =C15*RELAÇÃO!$D$8 -> 53.90625 | G15: 86 | H15: =G15*F15/1000 -> 4.6359375
... A28: 59012038000 | B28: CABECEIRA VIDRO | C28: 600 | D28: =C28*RELAÇÃO!$D$6 -> 234.375 | E28: =C28*RELAÇÃO!$D$4 -> 351.5625 | F28: =C28*RELAÇÃO!$D$8 -> 14.0625 | G28: 7 | H28: =G28*F28/1000 -> 0.0984375
A29: E1144262 | B29: PAINEL TETO | C29: 850 | D29: =C29*RELAÇÃO!$D$6 -> 332.03125 | E29: =C29*RELAÇÃO!$D$4 -> 498.04688 | F29: =C29*RELAÇÃO!$D$8 -> 19.921875 | G29: 7 | H29: =G29*F29/1000 -> 0.13945313
A30: E1144259 | B30: PAINEL TRASEIRO | C30: 1800 | D30: =C30*RELAÇÃO!$D$6 -> 703.125 | E30: =C30*RELAÇÃO!$D$4 -> 1054.6875 | F30: =C30*RELAÇÃO!$D$8 -> 42.1875 | G30: 7 | H30: =G30*F30/1000 -> 0.2953125
A31: 59011278300 | B31: CABECEIRA FECHADA | C31: 2700 | D31: =C31*RELAÇÃO!$D$6 -> 1054.6875 | E31: =C31*RELAÇÃO!$D$4 -> 1582.0312 | F31: =C31*RELAÇÃO!$D$8 -> 63.28125 | G31: 6 | H31: =G31*F31/1000 -> 0.3796875
A32: 59011308900 | B32: TANQUE | C32: 9200 | D32: =C32*RELAÇÃO!$D$6 -> 3593.75 | E32: =C32*RELAÇÃO!$D$4 -> 5390.625 | F32: =C32*RELAÇÃO!$D$8 -> 215.625 | G32: 1 | H32: =G32*F32/1000 -> 0.215625
A33: TOTAL ANUAL | G33: =SUM(G4:G32) -> 2839 | H33: =SUM(H4:H32) -> 157.30102
A34: OBS.: Considerando o sistema CD1266 + CE164 + C-pentano

Sheet HC X HFO
A1: AVALIAÇÃO
A2: ESPECIFICAÇÕES | B2: Unidade | C2: CD 1266+HC | D2: CD 1266+HFO
A3: Partes de Isocianato | B3: p | C3: 150 | D3: 150
A4: % Isocianato | B4: % | C4: =C3/(C3+C5+C7) -> 0.5859375 | D4: =D3/(D3+D5+D7) -> 0.57471264
A5: Partes de Poliol | B5: p | C5: 100 | D5: 100
A6: % Poliol | B6: % | C6: =C5/(C3+C5+C7) -> 0.390625 | D6: =D5/(D3+D5+D7) -> 0.38314176
A7: Partes de Expansor | B7: p | C7: 6 | D7: 11
A8: % Expansor | B8: % | C8: =C7/(C3+C5+C7) -> 0.0234375 | D8: =D7/(D3+D5+D7) -> 0.042145594
A9: % Poliol + Expansor | B9: % | C9: =(C5+C7)/(C3+C5+C7) -> 0.4140625 | D9: =(D5+D7)/(D3+D5+D7) -> 0.42528736
A10: Relação | B10: i/P | C10: =C3/(C5+C7) -> 1.4150943 | D10: =D3/(D5+D7) -> 1.3513514
A11: Vazão Máxima | B11: Kg/s | C11: 2.3 | D11: 2.3
A12: Vazão Isocianato | B12: Kg/s | C12: =C11/2 -> 1.15 | D12: =D11/2 -> 1.15
A13: Vazão Poliol | B13: Kg/s | C13: =(C9*C12)/C4 -> 0.81266667 | D13: =(D9*D12)/D4 -> 0.851
A14: Vazão Total Final | B14: Kg/s | C14: =C12+C13 -> 1.9626667 | D14: =D12+D13 -> 2.001
A15: Maior Volume Injeção | B15: Kg | C15: 16 | D15: 16
A16: Tempo Injeção | B16: s | C16: =C15/C14 -> 8.1521739 | D16: =D15/D14 -> 7.996002

Sheet PARAMETROS HC 1266 150-100-6
A1: PARÂMETROS PROCESSO
A2: ESPECIFICAÇÕES | B2: UNIDADE | C2: CR1157 POLIOL + CE 164 ISO | D2: CD 1266 POLIOL + HC + CE 164 ISO
A3: Partes de Isocianato | B3: p | C3: 130 | D3: 150
A4: % Isocianato - Total | B4: % | C4: =C3/(C3+C5+C7) -> 0.56521739 | D4: =D3/(D3+D5+D7) -> 0.5859375
A5: Partes de Poliol | B5: p | C5: 100 | D5: 100
A6: % Poliol - Total | B6: % | C6: =C5/(C3+C5+C7) -> 0.43478261 | D6: =D5/(D3+D5+D7) -> 0.390625
A7: Partes de HC | B7: p | C7: 0 | D7: 6
A8: % HC - Total | B8: % | C8: 0 | D8: =D7/(D3+D5+D7) -> 0.0234375
A9: % Poliol + HC - Total | B9: % | C9: 0 | D9: =(D5+D7)/(D3+D5+D7) -> 0.4140625
A10: Relação com HC incorporado | B10: I/P | C10: =C3/(C5+C7) -> 1.3 | D10: =D3/(D5+D7) -> 1.4150943
A11: Vazão Máxima | B11: Kg/s | D11: 2.3
A12: Vazão Isocianato | B12: Kg/s | D12: =D11/2 -> 1.15
A13: Vazão Poliol | B13: Kg/s | D13: =(D9*D12)/D4 -> 0.81266667
A14: Vazão Total Final | B14: Kg/s | D14: =D12+D13 -> 1.9626667
A15: Maior Volume Injeção | B15: Kg | D15: 16
A16: Tempo Injeção | B16: s | D16: =D15/D14 -> 8.1521739
A17: %HC Pré-Mix | B17: % | D17: =D7/(D5+D7) -> 0.056603774
A18: Densidade Relativa Poliol | B18: -- | C18: 1.1032 | D18: 1.1
A19: Densidade Relativa Isocianato | B19: -- | C19: 1.235 | D19: 1.235
A20: Densidade Absoluta Pentano | B20: -- | C20: -- | D20: 0.747
A21: Densidade Relativa Poliol+HC | B21: -- | C21: -- | D21: =(100/106*D18)+(6/100*D20) -> 1.0825558
A22: Temperatura Materiais | B22: ºC | C22: 22±3 | D22: 22±3
A23: Temperatura Peças | B23: ºC | C23: > 40 | D23: > 40
A24: Temperatura Moldes | B24: ºC | C24: 45±3 | D24: 45±3
A25: Pressão Injeção | B25: bar | C25: 140±5 | D25: 140±5
A26: Tempo Creme | B26: s | C26: 8 a 14 | D26: 6
A27: Tempo Gel | B27: s | C27: 55 a 80 | D27: 51
A28: Pega Livre | B28: s | D28: 100
A29: Densidade Livre | B29: Kg/m3 | C29: 25 a 31 | D29: 25.6
A30: Tempo de cura | B30: min | C30: 7 | D30: 8
A31: Viscosidade Poliol | B31: cPs | D31: 400
A32: Viscosidade Iso | B32: cPS | D32: 210
A33: Viscosidade Pentano | B33: cPs | D33: =0.00044*1000 -> 0.44
A34: Viscosidade Poliol+Pentano | B34: cPs | D34: =((100/106)*D31)+((6/106)*D33) -> 377.3834
A35: Viscosidade Poliol - Lab | B35: cPs | D35: 1810
A36: Viscosidade Poliol+Pentano - Lab | B36: cPs | D36: 0.632
A37: Compressão | B37: kPa | D37: 122 a 145

Sheet PARAMETROS HC 1266 154-100-6
A1: PARÂMETROS PROCESSO
A2: ESPECIFICAÇÕES | B2: UNIDADE | C2: CR1157 POLIOL + CE 164 ISO | D2: CD 1266 POLIOL + HC + CE 164 ISO
A3: Partes de Isocianato | B3: p | C3: 130 | D3: 154
A4: % Isocianato - Total | B4: % | C4: =C3/(C3+C5+C7) -> 0.56521739 | D4: =D3/(D3+D5+D7) -> 0.59230769
A5: Partes de Poliol | B5: p | C5: 100 | D5: 100
A6: % Poliol - Total | B6: % | C6: =C5/(C3+C5+C7) -> 0.43478261 | D6: =D5/(D3+D5+D7) -> 0.38461538
A7: Partes de HC | B7: p | C7: 0 | D7: 6
A8: % HC - Total | B8: % | C8: 0 | D8: =D7/(D3+D5+D7) -> 0.023076923
A9: % Poliol + HC - Total | B9: % | C9: 0 | D9: =(D5+D7)/(D3+D5+D7) -> 0.40769231
A10: Relação com HC incorporado | B10: I/P | C10: =C3/(C5+C7) -> 1.3 | D10: =D3/(D5+D7) -> 1.4528302
A11: Vazão Máxima | B11: Kg/s | D11: 2.3
A12: Vazão Isocianato | B12: Kg/s | D12: =D11/2 -> 1.15
A13: Vazão Poliol | B13: Kg/s | D13: =(D9*D12)/D4 -> 0.79155844
A14: Vazão Total Final | B14: Kg/s | D14: =D12+D13 -> 1.9415584
A15: Maior Volume Injeção | B15: Kg | D15: 16
A16: Tempo Injeção | B16: s | D16: =D15/D14 -> 8.2408027
A17: %HC Pré-Mix | B17: % | D17: =D7/(D5+D7) -> 0.056603774
A18: Densidade Relativa Poliol | B18: -- | C18: 1.1032 | D18: 1.1
A19: Densidade Relativa Isocianato | B19: -- | C19: 1.235 | D19: 1.235
A20: Densidade Absoluta Pentano | B20: -- | C20: -- | D20: 0.747
A21: Densidade Relativa Poliol+HC | B21: -- | C21: -- | D21: =(100/106*D18)+(6/100*D20) -> 1.0825558
A22: Temperatura Materiais | B22: ºC | C22: 22±3 | D22: 22±3
A23: Temperatura Peças | B23: ºC | C23: > 40 | D23: > 40
A24: Temperatura Moldes | B24: ºC | C24: 45±3 | D24: 45±3
A25: Pressão Injeção | B25: bar | C25: 140±5 | D25: 140±5
A26: Tempo Creme | B26: s | C26: 8 a 14 | D26: 6
A27: Tempo Gel | B27: s | C27: 55 a 80 | D27: 51
A28: Pega Livre | B28: s | D28: 100
A29: Densidade Livre | B29: Kg/m3 | C29: 25 a 31 | D29: 25.6
A30: Tempo de cura | B30: min | C30: 7 | D30: 8
A31: Viscosidade Poliol | B31: cPs | D31: 400
A32: Viscosidade Iso | B32: cPS | D32: 210
A33: Viscosidade Pentano | B33: cPs | D33: =0.00044*1000 -> 0.44
A34: Viscosidade Poliol+Pentano | B34: cPs | D34: =((100/106)*D31)+((6/106)*D33) -> 377.3834
A35: Viscosidade Poliol - Lab | B35: cPs | D35: 1810
A36: Viscosidade Poliol+Pentano - Lab | B36: cPs | D36: 0.632
A37: Compressão | B37: kPa | D37: 122 a 145

Sheet PARAMETROS HC 2610
A1: PARÂMETROS PROCESSO
A2: ESPECIFICAÇÕES | B2: UNIDADE | C2: CR1157 POLIOL + CE 164 ISO | D2: CR 2610 POLIOL + HC + CE 164 ISO
A3: Partes de Isocianato | B3: p | C3: 130 | D3: 143
A4: % Isocianato - Total | B4: % | C4: =C3/(C3+C5+C7) -> 0.56521739 | D4: =D3/(D3+D5+D7) -> 0.56761799
A5: Partes de Poliol | B5: p | C5: 100 | D5: 100
A6: % Poliol - Total | B6: % | C6: =C5/(C3+C5+C7) -> 0.43478261 | D6: =D5/(D3+D5+D7) -> 0.39693566
A7: Partes de HC | B7: p | C7: 0 | D7: 8.93
A8: % HC - Total | B8: % | C8: 0 | D8: =D7/(D3+D5+D7) -> 0.035446354
A9: % Poliol + HC - Total | B9: % | C9: 0 | D9: =(D5+D7)/(D3+D5+D7) -> 0.43238201
A10: Relação com HC incorporado | B10: I/P | C10: =C3/(C5+C7) -> 1.3 | D10: =D3/(D5+D7) -> 1.3127697
A11: Vazão Máxima | B11: Kg/s | D11: 2.3
A12: Vazão Isocianato | B12: Kg/s | D12: =D11/2 -> 1.15
A13: Vazão Poliol | B13: Kg/s | D13: =(D9*D12)/D4 -> 0.87601049
A14: Vazão Total Final | B14: Kg/s | D14: =D12+D13 -> 2.0260105
A15: Maior Volume Injeção | B15: Kg | D15: 16
A16: Tempo Injeção | B16: s | D16: =D15/D14 -> 7.8972938
A17: %HC Pré-Mix | B17: % | D17: =D7/(D5+D7) -> 0.081979253
A18: Densidade Relativa Poliol | B18: -- | C18: 1.1032 | D18: 1.09
A19: Densidade Relativa Isocianato | B19: -- | C19: 1.235 | D19: 1.235
A20: Densidade Absoluta Pentano | B20: -- | C20: -- | D20: 0.747
A21: Densidade Relativa Poliol+HC | B21: -- | C21: -- | D21: =(D18*((D5/(D5+D7))+(D20*((D7/(D5+D7)))))) -> 1.0673926
A22: Temperatura Materiais | B22: ºC | C22: 22±3 | D22: 22±2
A23: Temperatura Cabeçote | B23: ºC | D23: 25±7
A24: Temperatura Peças | B24: ºC | C24: > 40 | D24: > 40
A25: Temperatura Moldes | B25: ºC | C25: 45±3 | D25: 45±3
A26: Pressão Injeção | B26: bar | C26: 140±5 | D26: 140±5
A27: Tempo Creme | B27: s | C27: 8 a 14 | D27: 5
A28: Tempo Gel | B28: s | C28: 55 a 80 | D28: 50
A29: Pega Livre | B29: s | D29: 71
A30: Densidade Livre | B30: Kg/m3 | C30: 25 a 31 | D30: 24.2
A31: Tempo de cura | B31: min | C31: 7 | D31: 7
A32: Viscosidade Poliol | B32: cPs | D32: 2240
A33: Viscosidade Iso | B33: cPS | D33: 210
A34: Viscosidade Pentano | B34: cPs | D34: =0.00044*1000 -> 0.44
A35: Viscosidade Poliol+Pentano | B35: cPs | D35: =((D5/(D5+D7))*D32)+((D7/(D5+D7))*D34) -> 2056.4025
A36: Viscosidade Poliol - Lab | B36: cPs | D36: 3594
A37: Viscosidade Poliol+Pentano - Lab | B37: cPs | D37: 0.443
A38: Compressão | B38: kPa | D38: 122 a 145

Sheet PARAMETROS HC 2610 08 02 2023
A1: PARÂMETROS PROCESSO - COM RETARDANTE A CHAMA
A2: ESPECIFICAÇÕES | B2: UNIDADE | C2: CR1157 POLIOL + CE 164 ISO | D2: CR 2610 POLIOL + HC + CE 164 ISO
A3: Partes de Isocianato | B3: p | C3: 130 | D3: 143
A4: % Isocianato - Total | B4: % | C4: =C3/(C3+C5+C7) -> 0.56521739 | D4: =D3/(D3+D5+D7) -> 0.56761799
A5: Partes de Poliol | B5: p | C5: 100 | D5: 100
A6: % Poliol - Total | B6: % | C6: =C5/(C3+C5+C7) -> 0.43478261 | D6: =D5/(D3+D5+D7) -> 0.39693566
A7: Partes de HC | B7: p | C7: 0 | D7: 8.93
A8: % HC - Total | B8: % | C8: 0 | D8: =D7/(D3+D5+D7) -> 0.035446354
A9: % Poliol + HC - Total | B9: % | C9: 0 | D9: =(D5+D7)/(D3+D5+D7) -> 0.43238201
A10: Relação com HC incorporado | B10: I/P | C10: =C3/(C5+C7) -> 1.3 | D10: =D3/(D5+D7) -> 1.3127697
A11: Vazão Máxima | B11: Kg/s | D11: 2.3
A12: Vazão Isocianato | B12: Kg/s | D12: =D11/2 -> 1.15
A13: Vazão Poliol | B13: Kg/s | D13: =(D9*D12)/D4 -> 0.87601049
A14: Vazão Total Final | B14: Kg/s | D14: =D12+D13 -> 2.0260105
A15: Maior Volume Injeção | B15: Kg | D15: 16
A16: Tempo Injeção | B16: s | D16: =D15/D14 -> 7.8972938
A17: %HC Pré-Mix | B17: % | D17: =D7/(D5+D7) -> 0.081979253
A18: Densidade Relativa Poliol | B18: -- | C18: 1.1032 | D18: 1.108
A19: Densidade Relativa Isocianato | B19: -- | C19: 1.235 | D19: 1.235
A20: Densidade Absoluta Pentano | B20: -- | C20: -- | D20: 0.747
A21: Densidade Relativa Poliol+HC | B21: -- | C21: -- | D21: =(D18*((D5/(D5+D7))+(D20*((D7/(D5+D7)))))) -> 1.0850192
A22: Temperatura Materiais | B22: ºC | C22: 22±3 | D22: 22±2
A23: Temperatura Cabeçote | B23: ºC | D23: 25±7
A24: Temperatura Peças | B24: ºC | C24: > 40 | D24: > 40
A25: Temperatura Moldes | B25: ºC | C25: 45±3 | D25: 45±3
A26: Pressão Injeção | B26: bar | C26: 140±5 | D26: 140±5
A27: Tempo Creme | B27: s | C27: 8 a 14 | D27: 5
A28: Tempo Gel | B28: s | C28: 55 a 80 | D28: 35 - 50
A29: Pega Livre | B29: s | D29: 55 - 76
A30: Densidade Livre | B30: Kg/m3 | C30: 25 a 31 | D30: 24,3 - 25,2
A31: Tempo de cura | B31: min | C31: 7 | D31: 7
A32: Viscosidade Poliol | B32: cPs | D32: 2132
A33: Viscosidade Iso | B33: cPS | D33: 210
A34: Viscosidade Pentano | B34: cPs | D34: =0.00044*1000 -> 0.44
A35: Viscosidade Poliol+Pentano | B35: cPs | D35: =((D5/(D5+D7))*D32)+((D7/(D5+D7))*D34) -> 1957.2563
A36: Viscosidade Poliol - Lab | B36: cPs | D36: 3594
A37: Viscosidade Poliol+Pentano - Lab | B37: cPs | D37: 0.443
A38: Compressão | B38: kPa | D38: 122 a 145

Sheet PARAMETROS HC 2610 17 03 2023
A1: PARÂMETROS PROCESSO - COM RETARDANTE A CHAMA - CABEÇOTE 1 RFG
A2: ESPECIFICAÇÕES | B2: UNIDADE | C2: CR1157 POLIOL + CE 164 ISO | D2: CR 2610 POLIOL + HC + CE 164 ISO
A3: Partes de Isocianato | B3: p | C3: 130 | D3: 146
A4: % Isocianato - Total | B4: % | C4: =C3/(C3+C5+C7) -> 0.56521739 | D4: =D3/(D3+D5+D7) -> 0.57270623
A5: Partes de Poliol | B5: p | C5: 100 | D5: 100
A6: % Poliol - Total | B6: % | C6: =C5/(C3+C5+C7) -> 0.43478261 | D6: =D5/(D3+D5+D7) -> 0.39226454
A7: Partes de HC | B7: p | C7: 0 | D7: 8.93
A8: % HC - Total | B8: % | C8: 0 | D8: =D7/(D3+D5+D7) -> 0.035029224
A9: % Poliol + HC - Total | B9: % | C9: 0 | D9: =(D5+D7)/(D3+D5+D7) -> 0.42729377
A10: Relação com HC incorporado | B10: I/P | C10: =C3/(C5+C7) -> 1.3 | D10: =D3/(D5+D7) -> 1.3403103
A11: Vazão Máxima | B11: Kg/s | D11: 2.3
A12: Vazão Isocianato | B12: Kg/s | D12: =D11/2 -> 1.15
A13: Vazão Poliol | B13: Kg/s | D13: =(D9*D12)/D4 -> 0.85801027
A14: Vazão Total Final | B14: Kg/s | D14: =D12+D13 -> 2.0080103
A15: Maior Volume Injeção | B15: Kg | D15: 16
A16: Tempo Injeção | B16: s | D16: =D15/D14 -> 7.9680867
A17: %HC Pré-Mix | B17: % | D17: =D7/(D5+D7) -> 0.081979253
A18: Densidade Relativa Poliol | B18: -- | C18: 1.1032 | D18: 1.108
A19: Densidade Relativa Isocianato | B19: -- | C19: 1.235 | D19: 1.235
A20: Densidade Absoluta Pentano | B20: -- | C20: -- | D20: 0.747
A21: Densidade Relativa Poliol+HC | B21: -- | C21: -- | D21: =(D18*((D5/(D5+D7))+(D20*((D7/(D5+D7)))))) -> 1.0850192
A22: Temperatura Materiais | B22: ºC | C22: 22±3 | D22: 22±2
A23: Temperatura Cabeçote | B23: ºC | D23: 25±7
A24: Temperatura Peças | B24: ºC | C24: > 40 | D24: > 40
A25: Temperatura Moldes | B25: ºC | C25: 45±3 | D25: 45±3
A26: Pressão Injeção | B26: bar | C26: 140±5 | D26: 140±5
A27: Tempo Creme | B27: s | C27: 8 a 14 | D27: 5
A28: Tempo Gel | B28: s | C28: 55 a 80 | D28: 35 - 50
A29: Pega Livre | B29: s | D29: 55 - 76
A30: Densidade Livre | B30: Kg/m3 | C30: 25 a 31 | D30: 24,3 - 25,2
A31: Tempo de cura | B31: min | C31: 7 | D31: 7
A32: Viscosidade Poliol | B32: cPs | D32: 2132
A33: Viscosidade Iso | B33: cPS | D33: 210
A34: Viscosidade Pentano | B34: cPs | D34: =0.00044*1000 -> 0.44
A35: Viscosidade Poliol+Pentano | B35: cPs | D35: =((D5/(D5+D7))*D32)+((D7/(D5+D7))*D34) -> 1957.2563
A36: Viscosidade Poliol - Lab | B36: cPs | D36: 3594
A37: Viscosidade Poliol+Pentano - Lab | B37: cPs | D37: 0.443
A38: Compressão | B38: kPa | D38: 122 a 145
A39: 17/03/2023 - Mudança relação de 1,31 para 1,34, para diminuir a pressão interna da reação

Sheet HC 2610 16 05 2023 CAB1 
A1: PARÂMETROS PROCESSO - COM RETARDANTE A CHAMA - CABEÇOTE 1 RFG
A2: ESPECIFICAÇÕES | B2: UNIDADE | C2: CR1157 POLIOL + CE 164 ISO | D2: CR 2610 POLIOL + HC + CE 164 ISO
A3: Partes de Isocianato | B3: p | C3: 130 | D3: 146
A4: % Isocianato - Total | B4: % | C4: =C3/(C3+C5+C7) -> 0.56521739 | D4: =D3/(D3+D5+D7) -> 0.56729873
A5: Partes de Poliol | B5: p | C5: 100 | D5: 100
A6: % Poliol - Total | B6: % | C6: =C5/(C3+C5+C7) -> 0.43478261 | D6: =D5/(D3+D5+D7) -> 0.38856077
A7: Partes de HC | B7: p | C7: 0 | D7: 11.36
A8: % HC - Total | B8: % | C8: 0 | D8: =D7/(D3+D5+D7) -> 0.044140504
A9: % Poliol + HC - Total | B9: % | C9: 0 | D9: =(D5+D7)/(D3+D5+D7) -> 0.43270127
A10: Relação com HC incorporado | B10: I/P | C10: =C3/(C5+C7) -> 1.3 | D10: =D3/(D5+D7) -> 1.3110632
A11: Vazão Máxima | B11: Kg/s | D11: 2.3
A12: Vazão Isocianato | B12: Kg/s | D12: =D11/2 -> 1.15
A13: Vazão Poliol | B13: Kg/s | D13: =(D9*D12)/D4 -> 0.87715068
A14: Vazão Total Final | B14: Kg/s | D14: =D12+D13 -> 2.0271507
A15: Maior Volume Injeção | B15: Kg | D15: 16
A16: Tempo Injeção | B16: s | D16: =D15/D14 -> 7.8928518
A17: %HC Pré-Mix | B17: % | D17: =D7/(D5+D7) -> 0.10201149
A18: Densidade Relativa Poliol | B18: -- | C18: 1.1032 | D18: 1.09
A19: Densidade Relativa Isocianato | B19: -- | C19: 1.235 | D19: 1.235
A20: Densidade Absoluta Pentano | B20: -- | C20: -- | D20: 0.747
A21: Densidade Relativa Poliol+HC | B21: -- | C21: -- | D21: =(D18*((D5/(D5+D7))+(D20*((D7/(D5+D7)))))) -> 1.0618683
A22: Temperatura Materiais | B22: ºC | C22: 22±3 | D22: 24±2
A23: Temperatura Cabeçote | B23: ºC | D23: 25±7
A24: Temperatura Peças | B24: ºC | C24: > 40 | D24: > 40
A25: Temperatura Moldes | B25: ºC | C25: 45±3 | D25: 43±3
A26: Pressão Injeção | B26: bar | C26: 140±5 | D26: 140±5
A27: Tempo Creme | B27: s | C27: 8 a 14 | D27: 4 - 8
A28: Tempo Gel | B28: s | C28: 55 a 80 | D28: 40 - 55
A29: Pega Livre | B29: s | D29: 55 - 75
A30: Densidade Livre | B30: Kg/m3 | C30: 25 a 31 | D30: 24,0 - 26,0
A31: Tempo de cura | B31: min | C31: 7 | D31: 7
A32: Viscosidade Poliol | B32: cPs | D32: 2132
A33: Viscosidade Iso | B33: cPS | D33: 210
A34: Viscosidade Pentano | B34: cPs | D34: =0.00044*1000 -> 0.44
A35: Viscosidade Poliol+Pentano | B35: cPs | D35: =((D5/(D5+D7))*D32)+((D7/(D5+D7))*D34) -> 1914.5564
A36: Viscosidade Poliol - Lab | B36: cPs | D36: 3594
A37: Viscosidade Poliol+Pentano - Lab | B37: cPs | D37: 0.443
A38: Compressão | B38: kPa | D38: 122 a 145
A39: 16/05/2023 - Separação dos parametros por cabeçote

Sheet HC 2610 15 05 2023 CAB 2
A1: PARÂMETROS PROCESSO - COM RETARDANTE A CHAMA - CABEÇOTE 2
A2: ESPECIFICAÇÕES | B2: UNIDADE | C2: CR1157 POLIOL + CE 164 ISO | D2: CR 2610 POLIOL + HC + CE 164 ISO
A3: Partes de Isocianato | B3: p | C3: 130 | D3: 149.2
A4: % Isocianato - Total | B4: % | C4: =C3/(C3+C5+C7) -> 0.56521739 | D4: =D3/(D3+D5+D7) -> 0.57261283
A5: Partes de Poliol | B5: p | C5: 100 | D5: 100
A6: % Poliol - Total | B6: % | C6: =C5/(C3+C5+C7) -> 0.43478261 | D6: =D5/(D3+D5+D7) -> 0.38378876
A7: Partes de HC | B7: p | C7: 0 | D7: 11.36
A8: % HC - Total | B8: % | C8: 0 | D8: =D7/(D3+D5+D7) -> 0.043598403
A9: % Poliol + HC - Total | B9: % | C9: 0 | D9: =(D5+D7)/(D3+D5+D7) -> 0.42738717
A10: Relação com HC incorporado | B10: I/P | C10: =C3/(C5+C7) -> 1.3 | D10: =D3/(D5+D7) -> 1.3397989
A11: Vazão Máxima | B11: Kg/s | D11: 2.3
A12: Vazão Isocianato | B12: Kg/s | D12: =D11/2 -> 1.15
A13: Vazão Poliol | B13: Kg/s | D13: =(D9*D12)/D4 -> 0.8583378
A14: Vazão Total Final | B14: Kg/s | D14: =D12+D13 -> 2.0083378
A15: Maior Volume Injeção | B15: Kg | D15: 16
A16: Tempo Injeção | B16: s | D16: =D15/D14 -> 7.9667873
A17: %HC Pré-Mix | B17: % | D17: =D7/(D5+D7) -> 0.10201149
A18: Densidade Relativa Poliol | B18: -- | C18: 1.1032 | D18: 1.09
A19: Densidade Relativa Isocianato | B19: -- | C19: 1.235 | D19: 1.235
A20: Densidade Absoluta Pentano | B20: -- | C20: -- | D20: 0.747
A21: Densidade Relativa Poliol+HC | B21: -- | C21: -- | D21: =(D18*((D5/(D5+D7))+(D20*((D7/(D5+D7)))))) -> 1.0618683
A22: Temperatura Materiais | B22: ºC | C22: 22±3 | D22: (Quente)22±2; (Frio) 24±2
A23: Temperatura Cabeçote | B23: ºC | D23: (Quente) 24±3; (Frio) 25±5
A24: Temperatura Peças | B24: ºC | C24: > 40 | D24: > 40
A25: Temperatura Moldes | B25: ºC | C25: 45±3 | D25: 45±5
A26: Pressão Injeção | B26: bar | C26: 140±5 | D26: 130±5
A27: Tempo Creme | B27: s | C27: 8 a 14 | D27: 4 - 8
A28: Tempo Gel | B28: s | C28: 55 a 80 | D28: 40 - 55
A29: Pega Livre | B29: s | D29: 55 - 75
A30: Densidade Livre | B30: Kg/m3 | C30: 25 a 31 | D30: 24,0 - 26,0
A31: Tempo de cura | B31: min | C31: 7 | D31: 7
A32: Viscosidade Poliol | B32: cPs | D32: 2132
A33: Viscosidade Iso | B33: cPS | D33: 210
A34: Viscosidade Pentano | B34: cPs | D34: =0.00044*1000 -> 0.44
A35: Viscosidade Poliol+Pentano | B35: cPs | D35: =((D5/(D5+D7))*D32)+((D7/(D5+D7))*D34) -> 1914.5564
A36: Viscosidade Poliol - Lab | B36: cPs | D36: 3594
A37: Viscosidade Poliol+Pentano - Lab | B37: cPs | D37: 0.443
A38: Compressão | B38: kPa | D38: 140 - 180
A39: 17/03/2023 - Mudança relação de 1,31 para 1,34, para diminuir a pressão interna da reação
A41: 15/5/2023 - Mudança na proporção de gás pentano para 10,2%

Sheet HC 2610 24 05 2023 CAB1 
A1: PARÂMETROS PROCESSO - COM RETARDANTE A CHAMA - CABEÇOTE 1 RFG
A2: ESPECIFICAÇÕES | B2: UNIDADE | C2: CR1157 POLIOL + CE 164 ISO | D2: CR 2610 POLIOL + HC + CE 164 ISO | E2: Tolerâncias
A3: Partes de Isocianato | B3: p | C3: 130 | D3: 149.2
A4: % Isocianato - Total | B4: % | C4: =C3/(C3+C5+C7) -> 0.56521739 | D4: =D3/(D3+D5+D7) -> 0.57261283
A5: Partes de Poliol | B5: p | C5: 100 | D5: 100
A6: % Poliol - Total | B6: % | C6: =C5/(C3+C5+C7) -> 0.43478261 | D6: =D5/(D3+D5+D7) -> 0.38378876
A7: Partes de HC | B7: p | C7: 0 | D7: 11.36
A8: % HC - Total | B8: % | C8: 0 | D8: =D7/(D3+D5+D7) -> 0.043598403
A9: % Poliol + HC - Total | B9: % | C9: 0 | D9: =(D5+D7)/(D3+D5+D7) -> 0.42738717
A10: Relação com HC incorporado | B10: I/P | C10: =C3/(C5+C7) -> 1.3 | D10: =D3/(D5+D7) -> 1.3397989 | E10: ±0,03
A11: Vazão Máxima | B11: Kg/s | D11: 2.3
A12: Vazão Isocianato | B12: Kg/s | D12: =D11/2 -> 1.15
A13: Vazão Poliol | B13: Kg/s | D13: =(D9*D12)/D4 -> 0.8583378
A14: Vazão Total Final | B14: Kg/s | D14: =D12+D13 -> 2.0083378
A15: Maior Volume Injeção | B15: Kg | D15: 16
A16: Tempo Injeção | B16: s | D16: =D15/D14 -> 7.9667873
A17: %HC Pré-Mix | B17: % | D17: =D7/(D5+D7) -> 0.10201149
A18: Densidade Relativa Poliol | B18: -- | C18: 1.1032 | D18: 1.09
A19: Densidade Relativa Isocianato | B19: -- | C19: 1.235 | D19: 1.235
A20: Densidade Absoluta Pentano | B20: -- | C20: -- | D20: 0.747
A21: Densidade Relativa Poliol+HC | B21: -- | C21: -- | D21: =(D18*((D5/(D5+D7))+(D20*((D7/(D5+D7)))))) -> 1.0618683
A22: Temperatura Materiais | B22: ºC | C22: 22±3 | D22: (Quente)22±2; (Frio) 24±2 | E22: 24±2
A23: Temperatura Cabeçote | B23: ºC | D23: (Quente) 24±3; (Frio) 25±5 | E23: 25±7
A24: Temperatura Peças | B24: ºC | C24: > 40 | D24: > 40
A25: Temperatura Moldes | B25: ºC | C25: 45±3 | D25: 45±5 | E25: 43±3
A26: Pressão Injeção | B26: bar | C26: 140±5 | D26: 140±5 | E26: 140±5
A27: Tempo Creme | B27: s | C27: 8 a 14 | D27: 4 - 8
A28: Tempo Gel | B28: s | C28: 55 a 80 | D28: 40 - 55
A29: Pega Livre | B29: s | D29: 55 - 75
A30: Densidade Livre | B30: Kg/m3 | C30: 25 a 31 | D30: 24,0 - 26,0
A31: Tempo de cura | B31: min | C31: 7 | D31: 7
A32: Viscosidade Poliol | B32: cPs | D32: 2132
A33: Viscosidade Iso | B33: cPS | D33: 210
A34: Viscosidade Pentano | B34: cPs | D34: =0.00044*1000 -> 0.44
A35: Viscosidade Poliol+Pentano | B35: cPs | D35: =((D5/(D5+D7))*D32)+((D7/(D5+D7))*D34) -> 1914.5564
A36: Viscosidade Poliol - Lab | B36: cPs | D36: 3594
A37: Viscosidade Poliol+Pentano - Lab | B37: cPs | D37: 0.443
A38: Compressão | B38: kPa | D38: 140 - 180
A39: 16/05/2023 - Separação dos parametros por cabeçote 24/05/2023 - igualado a relação dos dois cabeçotes, saindo de 1,31 para 1,34 (facilita no cadastro do sistema)

Sheet HC 2610 26 07 2023 CAB1
A1: PARÂMETROS PROCESSO - COM RETARDANTE A CHAMA - CABEÇOTE 1 RFG
A2: ESPECIFICAÇÕES | B2: UNIDADE | C2: CR 2610 POLIOL + HC + CE 164 ISO | D2: Tolerâncias
A3: Vazão | B3: g/s | C3: 750 | D3: ±40
A4: Partes de Isocianato | B4: p | C4: 149.2
A5: % Isocianato - Total | B5: % | C5: =C4/(C4+C6+C8) -> 0.57261283
A6: Partes de Poliol | B6: p | C6: 100
A7: % Poliol - Total | B7: % | C7: =C6/(C4+C6+C8) -> 0.38378876
A8: Partes de HC | B8: p | C8: 11.36
A9: % HC - Total | B9: % | C9: =C8/(C4+C6+C8) -> 0.043598403
A10: % Poliol + HC - Total | B10: % | C10: =(C6+C8)/(C4+C6+C8) -> 0.42738717
A11: Relação com HC incorporado | B11: I/P | C11: =C4/(C6+C8) -> 1.3397989 | D11: ±0,03
A12: Vazão Máxima | B12: Kg/s | C12: 2.3
A13: Vazão Isocianato | B13: Kg/s | C13: =C12/2 -> 1.15
A14: Vazão Poliol | B14: Kg/s | C14: =(C10*C13)/C5 -> 0.8583378
A15: Vazão Total Final | B15: Kg/s | C15: =C13+C14 -> 2.0083378
A16: Maior Volume Injeção | B16: Kg | C16: 16
A17: Tempo Injeção | B17: s | C17: =C16/C15 -> 7.9667873
A18: %HC Pré-Mix | B18: % | C18: =C8/(C6+C8) -> 0.10201149
A19: Densidade Relativa Poliol | B19: -- | C19: 1.09
A20: Densidade Relativa Isocianato | B20: -- | C20: 1.235
A21: Densidade Absoluta Pentano | B21: -- | C21: 0.747
A22: Densidade Relativa Poliol+HC | B22: -- | C22: =(C19*((C6/(C6+C8))+(C21*((C8/(C6+C8)))))) -> 1.0618683
A23: Temperatura Materiais | B23: ºC | C23: 24 | D23: ±3
A24: Temperatura Cabeçote | B24: ºC | C24: 25 | D24: ±7
A25: Temperatura Peças | B25: ºC | C25: 45 | D25: ±5
A26: Temperatura Moldes | B26: ºC | C26: 45 | D26: ±5
A27: Pressão Injeção | B27: bar | C27: 130 | D27: ±5
A28: Tempo Creme | B28: s | C28: 4 - 8
A29: Tempo Gel | B29: s | C29: 40 - 55
A30: Pega Livre | B30: s | C30: 55 - 75
A31: Densidade Livre | B31: Kg/m3 | C31: 24,0 - 26,0
A32: Tempo de cura | B32: min | C32: 7
A33: Viscosidade Poliol | B33: cPs | C33: 2132
A34: Viscosidade Iso | B34: cPS | C34: 210
A35: Viscosidade Pentano | B35: cPs | C35: =0.00044*1000 -> 0.44
A36: Viscosidade Poliol+Pentano | B36: cPs | C36: =((C6/(C6+C8))*C33)+((C8/(C6+C8))*C35) -> 1914.5564
A37: Viscosidade Poliol - Lab | B37: cPs | C37: 3594
A38: Viscosidade Poliol+Pentano - Lab | B38: cPs | C38: 0.443
A39: Compressão | B39: kPa | C39: 130 a 180
A40: 16/05/2023 - Separação dos parametros por cabeçote 24/05/2023 - igualado a relação dos dois cabeçotes, saindo de 1,31 para 1,34 (facilita no cadastro do sistema) 26/07/2023 - inserido as tolerâncias para os parâmetros

Sheet HC 2610 26 07 2023 CAB2
A1: PARÂMETROS PROCESSO - COM RETARDANTE A CHAMA - CABEÇOTE 2
A2: ESPECIFICAÇÕES | B2: UNIDADE | C2: CR 2610 POLIOL + HC + CE 164 ISO | D2: Tolerâncias
A3: Vazão | B3: g/s | C3: 2200 | D3: ±110
A4: Partes de Isocianato | B4: p | C4: 149.2
A5: % Isocianato - Total | B5: % | C5: =C4/(C4+C6+C8) -> 0.57261283
A6: Partes de Poliol | B6: p | C6: 100
A7: % Poliol - Total | B7: % | C7: =C6/(C4+C6+C8) -> 0.38378876
A8: Partes de HC | B8: p | C8: 11.36
A9: % HC - Total | B9: % | C9: =C8/(C4+C6+C8) -> 0.043598403
A10: % Poliol + HC - Total | B10: % | C10: =(C6+C8)/(C4+C6+C8) -> 0.42738717
A11: Relação com HC incorporado | B11: I/P | C11: =C4/(C6+C8) -> 1.3397989 | D11: ±0,03
A12: Vazão Máxima | B12: Kg/s | C12: 2.3
A13: Vazão Isocianato | B13: Kg/s | C13: =C12/2 -> 1.15
A14: Vazão Poliol | B14: Kg/s | C14: =(C10*C13)/C5 -> 0.8583378
A15: Vazão Total Final | B15: Kg/s | C15: =C13+C14 -> 2.0083378
A16: Maior Volume Injeção | B16: Kg | C16: 16
A17: Tempo Injeção | B17: s | C17: =C16/C15 -> 7.9667873
A18: %HC Pré-Mix | B18: % | C18: =C8/(C6+C8) -> 0.10201149
A19: Densidade Relativa Poliol | B19: -- | C19: 1.09
A20: Densidade Relativa Isocianato | B20: -- | C20: 1.235
A21: Densidade Absoluta Pentano | B21: -- | C21: 0.747
A22: Densidade Relativa Poliol+HC | B22: -- | C22: =(C19*((C6/(C6+C8))+(C21*((C8/(C6+C8)))))) -> 1.0618683
A23: Temperatura Materiais | B23: ºC | C23: 24 | D23: ±3
A24: Temperatura Cabeçote | B24: ºC | C24: 25 | D24: ±7
A25: Temperatura Peças | B25: ºC | C25: 45 | D25: ±5
A26: Temperatura Moldes | B26: ºC | C26: 45 | D26: ±5
A27: Pressão Injeção | B27: bar | C27: 130 | D27: ±5
A28: Tempo Creme | B28: s | C28: 4 - 8
A29: Tempo Gel | B29: s | C29: 40 - 55
A30: Pega Livre | B30: s | C30: 55 - 75
A31: Densidade Livre | B31: Kg/m3 | C31: 24,0 - 26,0
A32: Tempo de cura | B32: min | C32: 7
A33: Viscosidade Poliol | B33: cPs | C33: 2132
A34: Viscosidade Iso | B34: cPS | C34: 210
A35: Viscosidade Pentano | B35: cPs | C35: =0.00044*1000 -> 0.44
A36: Viscosidade Poliol+Pentano | B36: cPs | C36: =((C6/(C6+C8))*C33)+((C8/(C6+C8))*C35) -> 1914.5564
A37: Viscosidade Poliol - Lab | B37: cPs | C37: 3594
A38: Viscosidade Poliol+Pentano - Lab | B38: cPs | C38: 0.443
A39: Compressão | B39: kPa | C39: 130 a 180
A40: 16/05/2023 - Separação dos parametros por cabeçote 24/05/2023 - igualado a relação dos dois cabeçotes, saindo de 1,31 para 1,34 (facilita no cadastro do sistema) 26/07/2023 - inserido as tolerâncias para os parâmetros

Sheet HC 2610 21 09 2023 CAB1
A1: PARÂMETROS PROCESSO - COM RETARDANTE A CHAMA - CABEÇOTE 1 RFG
A2: ESPECIFICAÇÕES | B2: UNIDADE | C2: CR 2610 POLIOL + HC + CE 164 ISO | D2: Tolerâncias
A3: Vazão | B3: g/s | C3: 750 | D3: ±40
A4: Partes de Isocianato | B4: p | C4: 148
A5: % Isocianato - Total | B5: % | C5: =C4/(C4+C6+C8) -> 0.57331009
A6: Partes de Poliol | B6: p | C6: 100
A7: % Poliol - Total | B7: % | C7: =C6/(C4+C6+C8) -> 0.38737168
A8: Partes de HC | B8: p | C8: 10.15
A9: % HC - Total | B9: % | C9: =C8/(C4+C6+C8) -> 0.039318226
A10: % Poliol + HC - Total | B10: % | C10: =(C6+C8)/(C4+C6+C8) -> 0.42668991
A11: Relação com HC incorporado | B11: I/P | C11: =C4/(C6+C8) -> 1.3436223 | D11: ±0,03
A12: Vazão Máxima | B12: Kg/s | C12: 2.3
A13: Vazão Isocianato | B13: Kg/s | C13: =C12/2 -> 1.15
A14: Vazão Poliol | B14: Kg/s | C14: =(C10*C13)/C5 -> 0.85589527
A15: Vazão Total Final | B15: Kg/s | C15: =C13+C14 -> 2.0058953
A16: Maior Volume Injeção | B16: Kg | C16: 16
A17: Tempo Injeção | B17: s | C17: =C16/C15 -> 7.9764882
A18: %HC Pré-Mix | B18: % | C18: =C8/(C6+C8) -> 0.092147072
A19: Densidade Relativa Poliol | B19: -- | C19: 1.09
A20: Densidade Relativa Isocianato | B20: -- | C20: 1.235
A21: Densidade Absoluta Pentano | B21: -- | C21: 0.747
A22: Densidade Relativa Poliol+HC | B22: -- | C22: =(C19*((C6/(C6+C8))+(C21*((C8/(C6+C8)))))) -> 1.0645886
A23: Temperatura Materiais | B23: ºC | C23: 22 | D23: ±3
A24: Temperatura Cabeçote | B24: ºC | C24: 22 | D24: ±7
A25: Temperatura Peças | B25: ºC | C25: 45 | D25: ±5
A26: Temperatura Moldes | B26: ºC | C26: 45 | D26: ±5
A27: Pressão Injeção | B27: bar | C27: 130 | D27: ±5
A28: Tempo Creme | B28: s | C28: 4 - 8
A29: Tempo Gel | B29: s | C29: 40 - 55
A30: Pega Livre | B30: s | C30: 55 - 75
A31: Densidade Livre | B31: Kg/m3 | C31: 24,0 - 26,0
A32: Tempo de cura | B32: min | C32: 7
A33: Viscosidade Poliol | B33: cPs | C33: 2132
A34: Viscosidade Iso | B34: cPS | C34: 210
A35: Viscosidade Pentano | B35: cPs | C35: =0.00044*1000 -> 0.44
A36: Viscosidade Poliol+Pentano | B36: cPs | C36: =((C6/(C6+C8))*C33)+((C8/(C6+C8))*C35) -> 1935.583
A37: Viscosidade Poliol - Lab | B37: cPs | C37: 3594
A38: Viscosidade Poliol+Pentano - Lab | B38: cPs | C38: 0.443
A39: Compressão | B39: kPa | C39: 130 a 180
A40: 16/05/2023 - Separação dos parametros por cabeçote 24/05/2023 - igualado a relação dos dois cabeçotes, saindo de 1,31 para 1,34 (facilita no cadastro do sistema) 26/07/2023 - inserido as tolerâncias para os parâmetros 21/09/2023 - alteração % pentano para 9,21

Sheet HC 2610 21 09 2023 CAB2
A1: PARÂMETROS PROCESSO - COM RETARDANTE A CHAMA - CABEÇOTE 2
A2: ESPECIFICAÇÕES | B2: UNIDADE | C2: CR 2610 POLIOL + HC + CE 164 ISO | D2: Tolerâncias
A3: Vazão | B3: g/s | C3: 2200 | D3: ±110
A4: Partes de Isocianato | B4: p | C4: 148
A5: % Isocianato - Total | B5: % | C5: =C4/(C4+C6+C8) -> 0.57331009
A6: Partes de Poliol | B6: p | C6: 100
A7: % Poliol - Total | B7: % | C7: =C6/(C4+C6+C8) -> 0.38737168
A8: Partes de HC | B8: p | C8: 10.15
A9: % HC - Total | B9: % | C9: =C8/(C4+C6+C8) -> 0.039318226
A10: % Poliol + HC - Total | B10: % | C10: =(C6+C8)/(C4+C6+C8) -> 0.42668991
A11: Relação com HC incorporado | B11: I/P | C11: =C4/(C6+C8) -> 1.3436223 | D11: ±0,03
A12: Vazão Máxima | B12: Kg/s | C12: 2.3
A13: Vazão Isocianato | B13: Kg/s | C13: =C12/2 -> 1.15
A14: Vazão Poliol | B14: Kg/s | C14: =(C10*C13)/C5 -> 0.85589527
A15: Vazão Total Final | B15: Kg/s | C15: =C13+C14 -> 2.0058953
A16: Maior Volume Injeção | B16: Kg | C16: 16
A17: Tempo Injeção | B17: s | C17: =C16/C15 -> 7.9764882
A18: %HC Pré-Mix | B18: % | C18: =C8/(C6+C8) -> 0.092147072
A19: Densidade Relativa Poliol | B19: -- | C19: 1.09
A20: Densidade Relativa Isocianato | B20: -- | C20: 1.235
A21: Densidade Absoluta Pentano | B21: -- | C21: 0.747
A22: Densidade Relativa Poliol+HC | B22: -- | C22: =(C19*((C6/(C6+C8))+(C21*((C8/(C6+C8)))))) -> 1.0645886
A23: Temperatura Materiais | B23: ºC | C23: 22 | D23: ±3
A24: Temperatura Cabeçote | B24: ºC | C24: 22 | D24: ±7
A25: Temperatura Peças | B25: ºC | C25: 45 | D25: ±5
A26: Temperatura Moldes | B26: ºC | C26: 45 | D26: ±5
A27: Pressão Injeção | B27: bar | C27: 130 | D27: ±5
A28: Tempo Creme | B28: s | C28: 4 - 8
A29: Tempo Gel | B29: s | C29: 40 - 55
A30: Pega Livre | B30: s | C30: 55 - 75
A31: Densidade Livre | B31: Kg/m3 | C31: 24,0 - 26,0
A32: Tempo de cura | B32: min | C32: 7
A33: Viscosidade Poliol | B33: cPs | C33: 2132
A34: Viscosidade Iso | B34: cPS | C34: 210
A35: Viscosidade Pentano | B35: cPs | C35: =0.00044*1000 -> 0.44
A36: Viscosidade Poliol+Pentano | B36: cPs | C36: =((C6/(C6+C8))*C33)+((C8/(C6+C8))*C35) -> 1935.583
A37: Viscosidade Poliol - Lab | B37: cPs | C37: 3594
A38: Viscosidade Poliol+Pentano - Lab | B38: cPs | C38: 0.443
A39: Compressão | B39: kPa | C39: 130 a 180
A40: 16/05/2023 - Separação dos parametros por cabeçote 24/05/2023 - igualado a relação dos dois cabeçotes, saindo de 1,31 para 1,34 (facilita no cadastro do sistema) 26/07/2023 - inserido as tolerâncias para os parâmetros 21/09/2023 - alteração % pentano para 9,21

Sheet HC 2610 26 09 2023 CAB1
A1: PARÂMETROS PROCESSO - COM RETARDANTE A CHAMA - CABEÇOTE 1 RFG
A2: ESPECIFICAÇÕES | B2: UNIDADE | C2: CR 2610 POLIOL + HC + CE 164 ISO | D2: Tolerâncias
A3: Vazão | B3: g/s | C3: 750 | D3: ±40
A4: Partes de Isocianato | B4: p | C4: 146
A5: % Isocianato - Total | B5: % | C5: =C4/(C4+C6+C8) -> 0.57266131
A6: Partes de Poliol | B6: p | C6: 100
A7: % Poliol - Total | B7: % | C7: =C6/(C4+C6+C8) -> 0.39223377
A8: Partes de HC | B8: p | C8: 8.95
A9: % HC - Total | B9: % | C9: =C8/(C4+C6+C8) -> 0.035104923
A10: % Poliol + HC - Total | B10: % | C10: =(C6+C8)/(C4+C6+C8) -> 0.42733869
A11: Relação com HC incorporado | B11: I/P | C11: =C4/(C6+C8) -> 1.3400642 | D11: ±0,03
A12: Vazão Máxima | B12: Kg/s | C12: 2.3
A13: Vazão Isocianato | B13: Kg/s | C13: =C12/2 -> 1.15
A14: Vazão Poliol | B14: Kg/s | C14: =(C10*C13)/C5 -> 0.85816781
A15: Vazão Total Final | B15: Kg/s | C15: =C13+C14 -> 2.0081678
A16: Maior Volume Injeção | B16: Kg | C16: 16
A17: Tempo Injeção | B17: s | C17: =C16/C15 -> 7.9674617
A18: %HC Pré-Mix | B18: % | C18: =C8/(C6+C8) -> 0.082147774
A19: Densidade Relativa Poliol | B19: -- | C19: 1.09
A20: Densidade Relativa Isocianato | B20: -- | C20: 1.235
A21: Densidade Absoluta Pentano | B21: -- | C21: 0.747
A22: Densidade Relativa Poliol+HC | B22: -- | C22: =(C19*((C6/(C6+C8))+(C21*((C8/(C6+C8)))))) -> 1.0673461
A23: Temperatura Materiais | B23: ºC | C23: 22 | D23: ±3
A24: Temperatura Cabeçote | B24: ºC | C24: 22 | D24: ±7
A25: Temperatura Peças | B25: ºC | C25: 45 | D25: ±5
A26: Temperatura Moldes | B26: ºC | C26: 45 | D26: ±5
A27: Pressão Injeção | B27: bar | C27: 130 | D27: ±5
A28: Tempo Creme | B28: s | C28: 4 - 8
A29: Tempo Gel | B29: s | C29: 40 - 55
A30: Pega Livre | B30: s | C30: 55 - 75
A31: Densidade Livre | B31: Kg/m3 | C31: 24,0 - 26,0
A32: Tempo de cura | B32: min | C32: 7
A33: Viscosidade Poliol | B33: cPs | C33: 2132
A34: Viscosidade Iso | B34: cPS | C34: 210
A35: Viscosidade Pentano | B35: cPs | C35: =0.00044*1000 -> 0.44
A36: Viscosidade Poliol+Pentano | B36: cPs | C36: =((C6/(C6+C8))*C33)+((C8/(C6+C8))*C35) -> 1956.8971
A37: Viscosidade Poliol - Lab | B37: cPs | C37: 3594
A38: Viscosidade Poliol+Pentano - Lab | B38: cPs | C38: 0.443
A39: Compressão | B39: kPa | C39: 130 a 180
A40: 16/05/2023 - Separação dos parametros por cabeçote 24/05/2023 - igualado a relação dos dois cabeçotes, saindo de 1,31 para 1,34 (facilita no cadastro do sistema) 26/07/2023 - inserido as tolerâncias para os parâmetros 21/09/2023 - alteração % pentano para 9,21 26/09/2023 - alteração % pentano para 8,21

Sheet HC 2610 26 09 2023 CAB2
A1: PARÂMETROS PROCESSO - COM RETARDANTE A CHAMA - CABEÇOTE 2
A2: ESPECIFICAÇÕES | B2: UNIDADE | C2: CR 2610 POLIOL + HC + CE 164 ISO | D2: Tolerâncias
A3: Vazão | B3: g/s | C3: 2200 | D3: ±110
A4: Partes de Isocianato | B4: p | C4: 146
A5: % Isocianato - Total | B5: % | C5: =C4/(C4+C6+C8) -> 0.57266131
A6: Partes de Poliol | B6: p | C6: 100
A7: % Poliol - Total | B7: % | C7: =C6/(C4+C6+C8) -> 0.39223377
A8: Partes de HC | B8: p | C8: 8.95
A9: % HC - Total | B9: % | C9: =C8/(C4+C6+C8) -> 0.035104923
A10: % Poliol + HC - Total | B10: % | C10: =(C6+C8)/(C4+C6+C8) -> 0.42733869
A11: Relação com HC incorporado | B11: I/P | C11: =C4/(C6+C8) -> 1.3400642 | D11: ±0,03
A12: Vazão Máxima | B12: Kg/s | C12: 2.3
A13: Vazão Isocianato | B13: Kg/s | C13: =C12/2 -> 1.15
A14: Vazão Poliol | B14: Kg/s | C14: =(C10*C13)/C5 -> 0.85816781
A15: Vazão Total Final | B15: Kg/s | C15: =C13+C14 -> 2.0081678
A16: Maior Volume Injeção | B16: Kg | C16: 16
A17: Tempo Injeção | B17: s | C17: =C16/C15 -> 7.9674617
A18: %HC Pré-Mix | B18: % | C18: =C8/(C6+C8) -> 0.082147774
A19: Densidade Relativa Poliol | B19: -- | C19: 1.09
A20: Densidade Relativa Isocianato | B20: -- | C20: 1.235
A21: Densidade Absoluta Pentano | B21: -- | C21: 0.747
A22: Densidade Relativa Poliol+HC | B22: -- | C22: =(C19*((C6/(C6+C8))+(C21*((C8/(C6+C8)))))) -> 1.0673461
A23: Temperatura Materiais | B23: ºC | C23: 22 | D23: ±3
A24: Temperatura Cabeçote | B24: ºC | C24: 22 | D24: ±7
A25: Temperatura Peças | B25: ºC | C25: 45 | D25: ±5
A26: Temperatura Moldes | B26: ºC | C26: 45 | D26: ±5
A27: Pressão Injeção | B27: bar | C27: 130 | D27: ±5
A28: Tempo Creme | B28: s | C28: 4 - 8
A29: Tempo Gel | B29: s | C29: 40 - 55
A30: Pega Livre | B30: s | C30: 55 - 75
A31: Densidade Livre | B31: Kg/m3 | C31: 24,0 - 26,0
A32: Tempo de cura | B32: min | C32: 7
A33: Viscosidade Poliol | B33: cPs | C33: 2132
A34: Viscosidade Iso | B34: cPS | C34: 210
A35: Viscosidade Pentano | B35: cPs | C35: =0.00044*1000 -> 0.44
A36: Viscosidade Poliol+Pentano | B36: cPs | C36: =((C6/(C6+C8))*C33)+((C8/(C6+C8))*C35) -> 1956.8971
A37: Viscosidade Poliol - Lab | B37: cPs | C37: 3594
A38: Viscosidade Poliol+Pentano - Lab | B38: cPs | C38: 0.443
A39: Compressão | B39: kPa | C39: 130 a 180
A40: 16/05/2023 - Separação dos parametros por cabeçote 24/05/2023 - igualado a relação dos dois cabeçotes, saindo de 1,31 para 1,34 (facilita no cadastro do sistema) 26/07/2023 - inserido as tolerâncias para os parâmetros 21/09/2023 - alteração % pentano para 9,21 26/09/2023 - alteração % pentano para 8,21

Sheet HC 2610 25 10 2023 CAB2
A1: PARÂMETROS PROCESSO - COM RETARDANTE A CHAMA - CABEÇOTE 2
A2: ESPECIFICAÇÕES | B2: UNIDADE | C2: CR 2610 POLIOL + HC + CE 164 ISO | D2: Tolerâncias
A3: Vazão | B3: g/s | C3: 2200 | D3: ±110
A4: Partes de Isocianato | B4: p | C4: 148
A5: % Isocianato - Total | B5: % | C5: =C4/(C4+C6+C8) -> 0.57331009
A6: Partes de Poliol | B6: p | C6: 100
A7: % Poliol - Total | B7: % | C7: =C6/(C4+C6+C8) -> 0.38737168
A8: Partes de HC | B8: p | C8: 10.15
A9: % HC - Total | B9: % | C9: =C8/(C4+C6+C8) -> 0.039318226
A10: % Poliol + HC - Total | B10: % | C10: =(C6+C8)/(C4+C6+C8) -> 0.42668991
A11: Relação com HC incorporado | B11: I/P | C11: =C4/(C6+C8) -> 1.3436223 | D11: ±0,03
A12: Vazão Máxima | B12: Kg/s | C12: 2.3
A13: Vazão Isocianato | B13: Kg/s | C13: =C12/2 -> 1.15
A14: Vazão Poliol | B14: Kg/s | C14: =(C10*C13)/C5 -> 0.85589527
A15: Vazão Total Final | B15: Kg/s | C15: =C13+C14 -> 2.0058953
A16: Maior Volume Injeção | B16: Kg | C16: 16
A17: Tempo Injeção | B17: s | C17: =C16/C15 -> 7.9764882
A18: %HC Pré-Mix | B18: % | C18: =C8/(C6+C8) -> 0.092147072
A19: Densidade Relativa Poliol | B19: -- | C19: 1.09
A20: Densidade Relativa Isocianato | B20: -- | C20: 1.235
A21: Densidade Absoluta Pentano | B21: -- | C21: 0.747
A22: Densidade Relativa Poliol+HC | B22: -- | C22: =(C19*((C6/(C6+C8))+(C21*((C8/(C6+C8)))))) -> 1.0645886
A23: Temperatura Materiais | B23: ºC | C23: 22 | D23: ±3
A24: Temperatura Cabeçote | B24: ºC | C24: 22 | D24: ±7
A25: Temperatura Peças | B25: ºC | C25: 45 | D25: ±5
A26: Temperatura Moldes | B26: ºC | C26: 45 | D26: ±5
A27: Pressão Injeção | B27: bar | C27: 130 | D27: ±5
A28: Tempo Creme | B28: s | C28: 4 - 8
A29: Tempo Gel | B29: s | C29: 40 - 55
A30: Pega Livre | B30: s | C30: 55 - 75
A31: Densidade Livre | B31: Kg/m3 | C31: 24,0 - 26,0
A32: Tempo de cura | B32: min | C32: 7
A33: Viscosidade Poliol | B33: cPs | C33: 2132
A34: Viscosidade Iso | B34: cPS | C34: 210
A35: Viscosidade Pentano | B35: cPs | C35: =0.00044*1000 -> 0.44
A36: Viscosidade Poliol+Pentano | B36: cPs | C36: =((C6/(C6+C8))*C33)+((C8/(C6+C8))*C35) -> 1935.583
A37: Viscosidade Poliol - Lab | B37: cPs | C37: 3594
A38: Viscosidade Poliol+Pentano - Lab | B38: cPs | C38: 0.443
A39: Compressão | B39: kPa | C39: 130 a 180
A40: 16/05/2023 - Separação dos parametros por cabeçote 24/05/2023 - igualado a relação dos dois cabeçotes, saindo de 1,31 para 1,34 (facilita no cadastro do sistema) 26/07/2023 - inserido as tolerâncias para os parâmetros 21/09/2023 - alteração % pentano para 9,21 26/09/2023 - alteração % pentano para 8,21 25/10/2023 - alteração % pentano para 9,21 (produtos com geometria complexa com eventuais falta de preenchimento)

Sheet HC 2610 25 10 2023 CAB1
A1: PARÂMETROS PROCESSO - COM RETARDANTE A CHAMA - CABEÇOTE 1 RFG
A2: ESPECIFICAÇÕES | B2: UNIDADE | C2: CR 2610 POLIOL + HC + CE 164 ISO | D2: Tolerâncias
A3: Vazão | B3: g/s | C3: 500 | D3: ±40
A4: Partes de Isocianato | B4: p | C4: 148
A5: % Isocianato - Total | B5: % | C5: =C4/(C4+C6+C8) -> 0.57331009
A6: Partes de Poliol | B6: p | C6: 100
A7: % Poliol - Total | B7: % | C7: =C6/(C4+C6+C8) -> 0.38737168
A8: Partes de HC | B8: p | C8: 10.15
A9: % HC - Total | B9: % | C9: =C8/(C4+C6+C8) -> 0.039318226
A10: % Poliol + HC - Total | B10: % | C10: =(C6+C8)/(C4+C6+C8) -> 0.42668991
A11: Relação com HC incorporado | B11: I/P | C11: =C4/(C6+C8) -> 1.3436223 | D11: ±0,03
A12: Vazão Máxima | B12: Kg/s | C12: 2.3
A13: Vazão Isocianato | B13: Kg/s | C13: =C12/2 -> 1.15
A14: Vazão Poliol | B14: Kg/s | C14: =(C10*C13)/C5 -> 0.85589527
A15: Vazão Total Final | B15: Kg/s | C15: =C13+C14 -> 2.0058953
A16: Maior Volume Injeção | B16: Kg | C16: 16
A17: Tempo Injeção | B17: s | C17: =C16/C15 -> 7.9764882
A18: %HC Pré-Mix | B18: % | C18: =C8/(C6+C8) -> 0.092147072
A19: Densidade Relativa Poliol | B19: -- | C19: 1.09
A20: Densidade Relativa Isocianato | B20: -- | C20: 1.235
A21: Densidade Absoluta Pentano | B21: -- | C21: 0.747
A22: Densidade Relativa Poliol+HC | B22: -- | C22: =(C19*((C6/(C6+C8))+(C21*((C8/(C6+C8)))))) -> 1.0645886
A23: Temperatura Materiais | B23: ºC | C23: 22 | D23: ±3
A24: Temperatura Cabeçote | B24: ºC | C24: 22 | D24: ±7
A25: Temperatura Peças | B25: ºC | C25: 45 | D25: ±5
A26: Temperatura Moldes | B26: ºC | C26: 45 | D26: ±5
A27: Pressão Injeção | B27: bar | C27: 130 | D27: ±5
A28: Tempo Creme | B28: s | C28: 4 - 8
A29: Tempo Gel | B29: s | C29: 40 - 55
A30: Pega Livre | B30: s | C30: 55 - 75
A31: Densidade Livre | B31: Kg/m3 | C31: 24,0 - 26,0
A32: Tempo de cura | B32: min | C32: 7
A33: Viscosidade Poliol | B33: cPs | C33: 2132
A34: Viscosidade Iso | B34: cPS | C34: 210
A35: Viscosidade Pentano | B35: cPs | C35: =0.00044*1000 -> 0.44
A36: Viscosidade Poliol+Pentano | B36: cPs | C36: =((C6/(C6+C8))*C33)+((C8/(C6+C8))*C35) -> 1935.583
A37: Viscosidade Poliol - Lab | B37: cPs | C37: 3594
A38: Viscosidade Poliol+Pentano - Lab | B38: cPs | C38: 0.443
A39: Compressão | B39: kPa | C39: 130 a 180
A40: 16/05/2023 - Separação dos parametros por cabeçote 24/05/2023 - igualado a relação dos dois cabeçotes, saindo de 1,31 para 1,34 (facilita no cadastro do sistema) 26/07/2023 - inserido as tolerâncias para os parâmetros 21/09/2023 - alteração % pentano para 9,21 26/09/2023 - alteração % pentano para 8,21 25/10/2023 - alteração % pentano para 9,21 (produtos com geometria complexa com eventuais falta de preenchimento)

Sheet HC 2610 24 05 2024 CAB1
A1: PARÂMETROS PROCESSO - COM RETARDANTE A CHAMA - CABEÇOTE 1 RFG
A2: ESPECIFICAÇÕES | B2: UNIDADE | C2: CR 2610 POLIOL + HC + CE 164 ISO | D2: Tolerâncias
A3: Vazão | B3: g/s | C3: 650 | D3: ±40
A4: Partes de Isocianato | B4: p | C4: 148
A5: % Isocianato - Total | B5: % | C5: =C4/(C4+C6+C8) -> 0.57195857
A6: Partes de Poliol | B6: p | C6: 100
A7: % Poliol - Total | B7: % | C7: =C6/(C4+C6+C8) -> 0.38645849
A8: Partes de HC | B8: p | C8: 10.76
A9: % HC - Total | B9: % | C9: =C8/(C4+C6+C8) -> 0.041582934
A10: % Poliol + HC - Total | B10: % | C10: =(C6+C8)/(C4+C6+C8) -> 0.42804143
A11: Relação com HC incorporado | B11: I/P | C11: =C4/(C6+C8) -> 1.3362225 | D11: ±0,03
A12: Vazão Máxima | B12: Kg/s | C12: 2.3
A13: Vazão Isocianato | B13: Kg/s | C13: =C12/2 -> 1.15
A14: Vazão Poliol | B14: Kg/s | C14: =(C10*C13)/C5 -> 0.86063514
A15: Vazão Total Final | B15: Kg/s | C15: =C13+C14 -> 2.0106351
A16: Maior Volume Injeção | B16: Kg | C16: 16
A17: Tempo Injeção | B17: s | C17: =C16/C15 -> 7.9576845
A18: %HC Pré-Mix | B18: % | C18: =C8/(C6+C8) -> 0.097146984
A19: Densidade Relativa Poliol | B19: -- | C19: 1.09
A20: Densidade Relativa Isocianato | B20: -- | C20: 1.235
A21: Densidade Absoluta Pentano | B21: -- | C21: 0.747
A22: Densidade Relativa Poliol+HC | B22: -- | C22: =(C19*((C6/(C6+C8))+(C21*((C8/(C6+C8)))))) -> 1.0632098
A23: Temperatura Materiais | B23: ºC | C23: 22 | D23: ±3
A24: Temperatura Cabeçote | B24: ºC | C24: 22 | D24: ±5
A25: Temperatura Peças | B25: ºC | C25: 45 | D25: ±5
A26: Temperatura Moldes | B26: ºC | C26: 45 | D26: ±5
A27: Pressão Injeção | B27: bar | C27: 140 | D27: ±10
A28: Tempo Creme | B28: s | C28: 4 - 8
A29: Tempo Gel | B29: s | C29: 40 - 55
A30: Pega Livre | B30: s | C30: 55 - 75
A31: Densidade Livre | B31: Kg/m3 | C31: 24,0 - 26,0
A32: Tempo de cura | B32: min | C32: 7
A33: Viscosidade Poliol | B33: cPs | C33: 2132
A34: Viscosidade Iso | B34: cPS | C34: 210
A35: Viscosidade Pentano | B35: cPs | C35: =0.00044*1000 -> 0.44
A36: Viscosidade Poliol+Pentano | B36: cPs | C36: =((C6/(C6+C8))*C33)+((C8/(C6+C8))*C35) -> 1924.9254
A37: Viscosidade Poliol - Lab | B37: cPs | C37: 3594
A38: Viscosidade Poliol+Pentano - Lab | B38: cPs | C38: 0.443
A39: Compressão | B39: kPa | C39: 130 a 180
A40: 16/05/2023 - Separação dos parametros por cabeçote 24/05/2023 - igualado a relação dos dois cabeçotes, saindo de 1,31 para 1,34 (facilita no cadastro do sistema) 26/07/2023 - inserido as tolerâncias para os parâmetros 21/09/2023 - alteração % pentano para 9,21 26/09/2023 - alteração % pentano para 8,21 25/10/2023 - alteração % pentano para 9,21 (produtos com geometria complexa com eventuais falta de preenchimento) 24/05/2024 - alteração % pentano para 9,71% com previsão de chegada do frio

Sheet HC 2610 24 05 2024 CAB2
A1: PARÂMETROS PROCESSO - COM RETARDANTE A CHAMA - CABEÇOTE 2
A2: ESPECIFICAÇÕES | B2: UNIDADE | C2: CR 2610 POLIOL + HC + CE 164 ISO | D2: Tolerâncias
A3: Vazão | B3: g/s | C3: 2200 | D3: ±110
A4: Partes de Isocianato | B4: p | C4: 148
A5: % Isocianato - Total | B5: % | C5: =C4/(C4+C6+C8) -> 0.57195857
A6: Partes de Poliol | B6: p | C6: 100
A7: % Poliol - Total | B7: % | C7: =C6/(C4+C6+C8) -> 0.38645849
A8: Partes de HC | B8: p | C8: 10.76
A9: % HC - Total | B9: % | C9: =C8/(C4+C6+C8) -> 0.041582934
A10: % Poliol + HC - Total | B10: % | C10: =(C6+C8)/(C4+C6+C8) -> 0.42804143
A11: Relação com HC incorporado | B11: I/P | C11: =C4/(C6+C8) -> 1.3362225 | D11: ±0,03
A12: Vazão Máxima | B12: Kg/s | C12: 2.3
A13: Vazão Isocianato | B13: Kg/s | C13: =C12/2 -> 1.15
A14: Vazão Poliol | B14: Kg/s | C14: =(C10*C13)/C5 -> 0.86063514
A15: Vazão Total Final | B15: Kg/s | C15: =C13+C14 -> 2.0106351
A16: Maior Volume Injeção | B16: Kg | C16: 16
A17: Tempo Injeção | B17: s | C17: =C16/C15 -> 7.9576845
A18: %HC Pré-Mix | B18: % | C18: =C8/(C6+C8) -> 0.097146984
A19: Densidade Relativa Poliol | B19: -- | C19: 1.09
A20: Densidade Relativa Isocianato | B20: -- | C20: 1.235
A21: Densidade Absoluta Pentano | B21: -- | C21: 0.747
A22: Densidade Relativa Poliol+HC | B22: -- | C22: =(C19*((C6/(C6+C8))+(C21*((C8/(C6+C8)))))) -> 1.0632098
A23: Temperatura Materiais | B23: ºC | C23: 22 | D23: ±3
A24: Temperatura Cabeçote | B24: ºC | C24: 22 | D24: ±7
A25: Temperatura Peças | B25: ºC | C25: 45 | D25: ±5
A26: Temperatura Moldes | B26: ºC | C26: 45 | D26: ±5
A27: Pressão Injeção | B27: bar | C27: 130 | D27: ±5
A28: Tempo Creme | B28: s | C28: 4 - 8
A29: Tempo Gel | B29: s | C29: 40 - 55
A30: Pega Livre | B30: s | C30: 55 - 75
A31: Densidade Livre | B31: Kg/m3 | C31: 24,0 - 26,0
A32: Tempo de cura | B32: min | C32: 7
A33: Viscosidade Poliol | B33: cPs | C33: 2132
A34: Viscosidade Iso | B34: cPS | C34: 210
A35: Viscosidade Pentano | B35: cPs | C35: =0.00044*1000 -> 0.44
A36: Viscosidade Poliol+Pentano | B36: cPs | C36: =((C6/(C6+C8))*C33)+((C8/(C6+C8))*C35) -> 1924.9254
A37: Viscosidade Poliol - Lab | B37: cPs | C37: 3594
A38: Viscosidade Poliol+Pentano - Lab | B38: cPs | C38: 0.443
A39: Compressão | B39: kPa | C39: 130 a 180
A40: 16/05/2023 - Separação dos parametros por cabeçote 24/05/2023 - igualado a relação dos dois cabeçotes, saindo de 1,31 para 1,34 (facilita no cadastro do sistema) 26/07/2023 - inserido as tolerâncias para os parâmetros 21/09/2023 - alteração % pentano para 9,21 26/09/2023 - alteração % pentano para 8,21 25/10/2023 - alteração % pentano para 9,21 (produtos com geometria complexa com eventuais falta de preenchimento) 24/05/2024 - alteração % pentano para 9,71% com previsão de chegada do frio

Sheet HC 2610 06 02 2025 CAB2
A1: PARÂMETROS PROCESSO - COM RETARDANTE A CHAMA - CABEÇOTE 2
A2: ESPECIFICAÇÕES | B2: UNIDADE | C2: CR 2610 POLIOL + HC + CE 164 ISO | D2: Tolerâncias
A3: Vazão | B3: g/s | C3: 3000 | D3: ±110
A4: Partes de Isocianato | B4: p | C4: 148
A5: % Isocianato - Total | B5: % | C5: =C4/(C4+C6+C8) -> 0.57195857
A6: Partes de Poliol | B6: p | C6: 100
A7: % Poliol - Total | B7: % | C7: =C6/(C4+C6+C8) -> 0.38645849
A8: Partes de HC | B8: p | C8: 10.76
A9: % HC - Total | B9: % | C9: =C8/(C4+C6+C8) -> 0.041582934
A10: % Poliol + HC - Total | B10: % | C10: =(C6+C8)/(C4+C6+C8) -> 0.42804143
A11: Relação com HC incorporado | B11: I/P | C11: =C4/(C6+C8) -> 1.3362225 | D11: ±0,03
A12: Vazão Máxima | B12: Kg/s | C12: 2.3
A13: Vazão Isocianato | B13: Kg/s | C13: =C12/2 -> 1.15
A14: Vazão Poliol | B14: Kg/s | C14: =(C10*C13)/C5 -> 0.86063514
A15: Vazão Total Final | B15: Kg/s | C15: =C13+C14 -> 2.0106351
A16: Maior Volume Injeção | B16: Kg | C16: 16
A17: Tempo Injeção | B17: s | C17: =C16/C15 -> 7.9576845
A18: %HC Pré-Mix | B18: % | C18: =C8/(C6+C8) -> 0.097146984
A19: Densidade Relativa Poliol | B19: -- | C19: 1.09
A20: Densidade Relativa Isocianato | B20: -- | C20: 1.235
A21: Densidade Absoluta Pentano | B21: -- | C21: 0.65
A22: Densidade Relativa Poliol+HC | B22: -- | C22: =(C19*((C6/(C6+C8))+(C21*((C8/(C6+C8)))))) -> 1.0529384
A23: Temperatura Materiais | B23: ºC | C23: 22 | D23: ±3
A24: Temperatura Cabeçote | B24: ºC | C24: 22 | D24: ±5
A25: Temperatura Peças | B25: ºC | C25: 45 | D25: ±5
A26: Temperatura Moldes | B26: ºC | C26: 45 | D26: ±5
A27: Pressão Injeção | B27: bar | C27: 140 | D27: ±10
A28: Tempo Creme | B28: s | C28: 5
A29: Tempo Gel | B29: s | C29: 40 - 55
A30: Pega Livre | B30: s | C30: 55 - 75
A31: Densidade Livre | B31: Kg/m3 | C31: 24,0 - 27,0
A32: Tempo de cura | B32: min | C32: 7
A33: Viscosidade Poliol | B33: cPs | C33: 2132
A34: Viscosidade Iso | B34: cPS | C34: 210
A35: Viscosidade Pentano | B35: cPs | C35: =0.00044*1000 -> 0.44
A36: Viscosidade Poliol+Pentano | B36: cPs | C36: =((C6/(C6+C8))*C33)+((C8/(C6+C8))*C35) -> 1924.9254
A37: Viscosidade Poliol - Lab | B37: cPs | C37: 3594
A38: Viscosidade Poliol+Pentano - Lab | B38: cPs | C38: 0.443
A39: Compressão | B39: kPa | C39: 130 a 180
A40: 16/05/2023 - Separação dos parametros por cabeçote 24/05/2023 - igualado a relação dos dois cabeçotes, saindo de 1,31 para 1,34 (facilita no cadastro do sistema) 26/07/2023 - inserido as tolerâncias para os parâmetros 21/09/2023 - alteração % pentano para 9,21 26/09/2023 - alteração % pentano para 8,21 25/10/2023 - alteração % pentano para 9,21 (produtos com geometria complexa com eventuais falta de preenchimento) 24/05/2024 - alteração % pentano para 9,71% com previsão de chegada do frio 06/02/2025 - alteração vazão para 3 Kg/s e pressão no cabeçote 2 para 120Kgf/cm2, em função da mudança de vazão

Sheet Planilha1

Sheet PARAMETROS HC 1091 9
